Traceback (most recent call last):
  File "/Users/daynan/wb/OpenNightLights/venv/lib/python3.8/site-packages/jupyter_cache/executors/utils.py", line 51, in single_nb_execution
    executenb(
  File "/Users/daynan/wb/OpenNightLights/venv/lib/python3.8/site-packages/nbclient/client.py", line 1087, in execute
    return NotebookClient(nb=nb, resources=resources, km=km, **kwargs).execute()
  File "/Users/daynan/wb/OpenNightLights/venv/lib/python3.8/site-packages/nbclient/util.py", line 74, in wrapped
    return just_run(coro(*args, **kwargs))
  File "/Users/daynan/wb/OpenNightLights/venv/lib/python3.8/site-packages/nbclient/util.py", line 53, in just_run
    return loop.run_until_complete(coro)
  File "/Users/daynan/.pyenv/versions/3.8.2/lib/python3.8/asyncio/base_events.py", line 616, in run_until_complete
    return future.result()
  File "/Users/daynan/wb/OpenNightLights/venv/lib/python3.8/site-packages/nbclient/client.py", line 540, in async_execute
    await self.async_execute_cell(
  File "/Users/daynan/wb/OpenNightLights/venv/lib/python3.8/site-packages/nbclient/client.py", line 832, in async_execute_cell
    self._check_raise_for_error(cell, exec_reply)
  File "/Users/daynan/wb/OpenNightLights/venv/lib/python3.8/site-packages/nbclient/client.py", line 740, in _check_raise_for_error
    raise CellExecutionError.from_cell_and_msg(cell, exec_reply['content'])
nbclient.exceptions.CellExecutionError: An error occurred while executing the following cell:
------------------
import seaborn as sns
import matplotlib.pyplot as plt

fig, ax = plt.subplots(figsize=(15,5))
sns.kdeplot(dmsp1996_arr.flatten(), label='non-calibrated',legend=True, ax=ax)
sns.kdeplot(dmsp1996_clbr_arr.flatten(), label='calibrated',legend=True, ax=ax)
plt.legend(fontsize=20)
plt.title('Distribution of DMSP-OLS 1996 composite calibrated vs non (smoothed w/ Gaussian kernel)', fontsize=20);
------------------

[0;31m---------------------------------------------------------------------------[0m
[0;31mModuleNotFoundError[0m                       Traceback (most recent call last)
[0;32m<ipython-input-8-0a245eefe305>[0m in [0;36m<module>[0;34m[0m
[0;32m----> 1[0;31m [0;32mimport[0m [0mseaborn[0m [0;32mas[0m [0msns[0m[0;34m[0m[0;34m[0m[0m
[0m[1;32m      2[0m [0;32mimport[0m [0mmatplotlib[0m[0;34m.[0m[0mpyplot[0m [0;32mas[0m [0mplt[0m[0;34m[0m[0;34m[0m[0m
[1;32m      3[0m [0;34m[0m[0m
[1;32m      4[0m [0mfig[0m[0;34m,[0m [0max[0m [0;34m=[0m [0mplt[0m[0;34m.[0m[0msubplots[0m[0;34m([0m[0mfigsize[0m[0;34m=[0m[0;34m([0m[0;36m15[0m[0;34m,[0m[0;36m5[0m[0;34m)[0m[0;34m)[0m[0;34m[0m[0;34m[0m[0m
[1;32m      5[0m [0msns[0m[0;34m.[0m[0mkdeplot[0m[0;34m([0m[0mdmsp1996_arr[0m[0;34m.[0m[0mflatten[0m[0;34m([0m[0;34m)[0m[0;34m,[0m [0mlabel[0m[0;34m=[0m[0;34m'non-calibrated'[0m[0;34m,[0m[0mlegend[0m[0;34m=[0m[0;32mTrue[0m[0;34m,[0m [0max[0m[0;34m=[0m[0max[0m[0;34m)[0m[0;34m[0m[0;34m[0m[0m

[0;31mModuleNotFoundError[0m: No module named 'seaborn'
ModuleNotFoundError: No module named 'seaborn'

