Traceback (most recent call last):
  File "/Users/daynan/anaconda3/envs/onl/lib/python3.7/site-packages/jupyter_cache/executors/utils.py", line 56, in single_nb_execution
    record_timing=False,
  File "/Users/daynan/anaconda3/envs/onl/lib/python3.7/site-packages/nbclient/client.py", line 1082, in execute
    return NotebookClient(nb=nb, resources=resources, km=km, **kwargs).execute()
  File "/Users/daynan/anaconda3/envs/onl/lib/python3.7/site-packages/nbclient/util.py", line 74, in wrapped
    return just_run(coro(*args, **kwargs))
  File "/Users/daynan/anaconda3/envs/onl/lib/python3.7/site-packages/nbclient/util.py", line 53, in just_run
    return loop.run_until_complete(coro)
  File "/Users/daynan/anaconda3/envs/onl/lib/python3.7/asyncio/base_events.py", line 587, in run_until_complete
    return future.result()
  File "/Users/daynan/anaconda3/envs/onl/lib/python3.7/site-packages/nbclient/client.py", line 536, in async_execute
    cell, index, execution_count=self.code_cells_executed + 1
  File "/Users/daynan/anaconda3/envs/onl/lib/python3.7/site-packages/nbclient/client.py", line 827, in async_execute_cell
    self._check_raise_for_error(cell, exec_reply)
  File "/Users/daynan/anaconda3/envs/onl/lib/python3.7/site-packages/nbclient/client.py", line 735, in _check_raise_for_error
    raise CellExecutionError.from_cell_and_msg(cell, exec_reply['content'])
nbclient.exceptions.CellExecutionError: An error occurred while executing the following cell:
------------------
import geopandas as gpd
import json, geemap, ee

try:
        ee.Initialize()
except Exception as e:
        ee.Authenticate()
        ee.Initialize()

# location of shapefile locally
sydney_shp_path = "files/city_of_sydney_shapefile/sydney.shp"

# we read our shapefile in to a geopandas data frame using the geopandas.read_file method
# we'll make sure it's initiated in the EPSG 4326 CRS
sydney_gdf = gpd.read_file(sydney_shp_path, crs='EPSG:4326')

# define a helper function to put the geodataframe in the right format for constructing an ee object
def shp_to_ee_fmt(geodf):
    data = json.loads(geodf.to_json())
    return data['features'][0]['geometry']['coordinates']

# create the ee object
sydney = ee.Geometry.MultiPolygon(shp_to_ee_fmt(sydney_gdf))
------------------

[0;31m---------------------------------------------------------------------------[0m
[0;31mModuleNotFoundError[0m                       Traceback (most recent call last)
[0;32m<ipython-input-1-c4fb45d6bded>[0m in [0;36m<module>[0;34m[0m
[0;32m----> 1[0;31m [0;32mimport[0m [0mgeopandas[0m [0;32mas[0m [0mgpd[0m[0;34m[0m[0;34m[0m[0m
[0m[1;32m      2[0m [0;32mimport[0m [0mjson[0m[0;34m,[0m [0mgeemap[0m[0;34m,[0m [0mee[0m[0;34m[0m[0;34m[0m[0m
[1;32m      3[0m [0;34m[0m[0m
[1;32m      4[0m [0;32mtry[0m[0;34m:[0m[0;34m[0m[0;34m[0m[0m
[1;32m      5[0m         [0mee[0m[0;34m.[0m[0mInitialize[0m[0;34m([0m[0;34m)[0m[0;34m[0m[0;34m[0m[0m

[0;31mModuleNotFoundError[0m: No module named 'geopandas'
ModuleNotFoundError: No module named 'geopandas'

