Traceback (most recent call last):
  File "/Users/daynan/wb/OpenNightLights/venv/lib/python3.8/site-packages/jupyter_cache/executors/utils.py", line 51, in single_nb_execution
    executenb(
  File "/Users/daynan/wb/OpenNightLights/venv/lib/python3.8/site-packages/nbclient/client.py", line 1087, in execute
    return NotebookClient(nb=nb, resources=resources, km=km, **kwargs).execute()
  File "/Users/daynan/wb/OpenNightLights/venv/lib/python3.8/site-packages/nbclient/util.py", line 74, in wrapped
    return just_run(coro(*args, **kwargs))
  File "/Users/daynan/wb/OpenNightLights/venv/lib/python3.8/site-packages/nbclient/util.py", line 53, in just_run
    return loop.run_until_complete(coro)
  File "/Users/daynan/.pyenv/versions/3.8.2/lib/python3.8/asyncio/base_events.py", line 616, in run_until_complete
    return future.result()
  File "/Users/daynan/wb/OpenNightLights/venv/lib/python3.8/site-packages/nbclient/client.py", line 540, in async_execute
    await self.async_execute_cell(
  File "/Users/daynan/wb/OpenNightLights/venv/lib/python3.8/site-packages/nbclient/client.py", line 832, in async_execute_cell
    self._check_raise_for_error(cell, exec_reply)
  File "/Users/daynan/wb/OpenNightLights/venv/lib/python3.8/site-packages/nbclient/client.py", line 740, in _check_raise_for_error
    raise CellExecutionError.from_cell_and_msg(cell, exec_reply['content'])
nbclient.exceptions.CellExecutionError: An error occurred while executing the following cell:
------------------
# create a 200 km buffer around the center of Catalonia
aoi = ee.Geometry.Point([lon, lat]).buffer(200000);

# extract a number array from this region
arr = geemap.ee_to_numpy(viirs2019_12, region=aoi)

# create a histogram
import seaborn as sns
import matplotlib.pyplot as plt

fig, ax = plt.subplots(figsize=(15,5))
sns.kdeplot(arr.flatten(), label='region',legend=True, ax=ax)
ax.axvline(4, color='indianred', label='suggested threshold')
plt.legend(fontsize=20)
plt.title('Distribution of VIIRS-DNB from sample(smoothed w/ Gaussian kernel)', fontsize=20);
plt.ylabel('avg radiance')
plt.legend();
------------------

[0;31m---------------------------------------------------------------------------[0m
[0;31mModuleNotFoundError[0m                       Traceback (most recent call last)
[0;32m<ipython-input-3-a2efd5ce22c0>[0m in [0;36m<module>[0;34m[0m
[1;32m      6[0m [0;34m[0m[0m
[1;32m      7[0m [0;31m# create a histogram[0m[0;34m[0m[0;34m[0m[0;34m[0m[0m
[0;32m----> 8[0;31m [0;32mimport[0m [0mseaborn[0m [0;32mas[0m [0msns[0m[0;34m[0m[0;34m[0m[0m
[0m[1;32m      9[0m [0;32mimport[0m [0mmatplotlib[0m[0;34m.[0m[0mpyplot[0m [0;32mas[0m [0mplt[0m[0;34m[0m[0;34m[0m[0m
[1;32m     10[0m [0;34m[0m[0m

[0;31mModuleNotFoundError[0m: No module named 'seaborn'
ModuleNotFoundError: No module named 'seaborn'

