Traceback (most recent call last):
  File "/Users/daynan/wb/OpenNightLights/venv/lib/python3.8/site-packages/jupyter_cache/executors/utils.py", line 51, in single_nb_execution
    executenb(
  File "/Users/daynan/wb/OpenNightLights/venv/lib/python3.8/site-packages/nbclient/client.py", line 1087, in execute
    return NotebookClient(nb=nb, resources=resources, km=km, **kwargs).execute()
  File "/Users/daynan/wb/OpenNightLights/venv/lib/python3.8/site-packages/nbclient/util.py", line 74, in wrapped
    return just_run(coro(*args, **kwargs))
  File "/Users/daynan/wb/OpenNightLights/venv/lib/python3.8/site-packages/nbclient/util.py", line 53, in just_run
    return loop.run_until_complete(coro)
  File "/Users/daynan/.pyenv/versions/3.8.2/lib/python3.8/asyncio/base_events.py", line 616, in run_until_complete
    return future.result()
  File "/Users/daynan/wb/OpenNightLights/venv/lib/python3.8/site-packages/nbclient/client.py", line 540, in async_execute
    await self.async_execute_cell(
  File "/Users/daynan/wb/OpenNightLights/venv/lib/python3.8/site-packages/nbclient/client.py", line 832, in async_execute_cell
    self._check_raise_for_error(cell, exec_reply)
  File "/Users/daynan/wb/OpenNightLights/venv/lib/python3.8/site-packages/nbclient/client.py", line 740, in _check_raise_for_error
    raise CellExecutionError.from_cell_and_msg(cell, exec_reply['content'])
nbclient.exceptions.CellExecutionError: An error occurred while executing the following cell:
------------------
import geemap, ee
import pandas as pd
import matplotlib.pyplot as plt
import seaborn as sns

try:
        ee.Initialize()
except Exception as e:
        ee.Authenticate()
        ee.Initialize()

# identify a 500 meter buffer around our Point Of Interest (POI)
poi = ee.Geometry.Point(127.072483, 37.515817).buffer(500)

viirs = ee.ImageCollection("NOAA/VIIRS/DNB/MONTHLY_V1/VCMSLCFG").filterDate('2014-01-01','2020-5-31')
------------------

[0;31m---------------------------------------------------------------------------[0m
[0;31mModuleNotFoundError[0m                       Traceback (most recent call last)
[0;32m<ipython-input-1-a1411b0c8d14>[0m in [0;36m<module>[0;34m[0m
[1;32m      2[0m [0;32mimport[0m [0mpandas[0m [0;32mas[0m [0mpd[0m[0;34m[0m[0;34m[0m[0m
[1;32m      3[0m [0;32mimport[0m [0mmatplotlib[0m[0;34m.[0m[0mpyplot[0m [0;32mas[0m [0mplt[0m[0;34m[0m[0;34m[0m[0m
[0;32m----> 4[0;31m [0;32mimport[0m [0mseaborn[0m [0;32mas[0m [0msns[0m[0;34m[0m[0;34m[0m[0m
[0m[1;32m      5[0m [0;34m[0m[0m
[1;32m      6[0m [0;32mtry[0m[0;34m:[0m[0;34m[0m[0;34m[0m[0m

[0;31mModuleNotFoundError[0m: No module named 'seaborn'
ModuleNotFoundError: No module named 'seaborn'

